Workbook

Sheet Low-price monthly forecast
A1: Low-price monthly forecast
A2: NightWatch — Forecast · Base
A4: Variable / dimension | B4: 2026-10 | C4: 2026-11 | D4: 2026-12 | E4: 2027-01 | F4: 2027-02 | G4: 2027-03 | H4: 2027-04 | I4: 2027-05 | J4: 2027-06 | K4: 2027-07 | L4: 2027-08 | M4: 2027-09 | N4: 2027-10 | O4: 2027-11 | P4: 2027-12 | Q4: 2028-01 | R4: 2028-02 | S4: 2028-03
A5: NW Opening customers | B5: =SUM('Low-price monthly forecast'!B6,'Low-price monthly forecast'!B7,'Low-price monthly forecast'!B8,'Low-price monthly forecast'!B9) -> 0 | C5: =SUM('Low-price monthly forecast'!C6,'Low-price monthly forecast'!C7,'Low-price monthly forecast'!C8,'Low-price monthly forecast'!C9) -> 40 | D5: =SUM('Low-price monthly forecast'!D6,'Low-price monthly forecast'!D7,'Low-price monthly forecast'!D8,'Low-price monthly forecast'!D9) -> 78.4 | E5: =SUM('Low-price monthly forecast'!E6,'Low-price monthly forecast'!E7,'Low-price monthly forecast'!E8,'Low-price monthly forecast'!E9) -> 115.264 | F5: =SUM('Low-price monthly forecast'!F6,'Low-price monthly forecast'!F7,'Low-price monthly forecast'!F8,'Low-price monthly forecast'!F9) -> 150.65344 | G5: =SUM('Low-price monthly forecast'!G6,'Low-price monthly forecast'!G7,'Low-price monthly forecast'!G8,'Low-price monthly forecast'!G9) -> 184.6273 | H5: =SUM('Low-price monthly forecast'!H6,'Low-price monthly forecast'!H7,'Low-price monthly forecast'!H8,'Low-price monthly forecast'!H9) -> 217.24221 | I5: =SUM('Low-price monthly forecast'!I6,'Low-price monthly forecast'!I7,'Low-price monthly forecast'!I8,'Low-price monthly forecast'!I9) -> 248.55252 | ... S5: =SUM('Low-price monthly forecast'!S6,'Low-price monthly forecast'!S7,'Low-price monthly forecast'!S8,'Low-price monthly forecast'!S9) -> 500.41319
A6: Business | B6: =IF(IF(IF(ISERROR(DATE(2026,10,1)='Model inputs'!B33),DATE(2026,10,1)='Model inputs'!B33,IF('Model inputs'!B33="","",DATE(2026,10,1)='Model inputs'!B33))="",FALSE,IF(ISERROR(DATE(2026,10,1)='Model inputs'!B33),DATE(2026,10,1)='Model inputs'!B33,IF('Model inputs'!B33="","",DATE(2026,10,1)='Model inputs'!B33))),'Model inputs'!B91*'Model inputs'!B22,IF('Model inputs'!K78="","",'Model inputs'!K78)) -> 0 | C6: =IF(IF(IF(ISERROR(DATE(2026,11,1)='Model inputs'!B33),DATE(2026,11,1)='Model inputs'!B33,IF('Model inputs'!B33="","",DATE(2026,11,1)='Model inputs'!B33))="",FALSE,IF(ISERROR(DATE(2026,11,1)='Model inputs'!B33),DATE(2026,11,1)='Model inputs'!B33,IF('Model inputs'!B33="","",DATE(2026,11,1)='Model inputs'!B33))),'Model inputs'!B91*'Model inputs'!B22,IF('Low-price monthly forecast'!B21="","",'Low-price monthly forecast'!B21)) -> 4 | D6: =IF(IF(IF(ISERROR(DATE(2026,12,1)='Model inputs'!B33),DATE(2026,12,1)='Model inputs'!B33,IF('Model inputs'!B33="","",DATE(2026,12,1)='Model inputs'!B33))="",FALSE,IF(ISERROR(DATE(2026,12,1)='Model inputs'!B33),DATE(2026,12,1)='Model inputs'!B33,IF('Model inputs'!B33="","",DATE(2026,12,1)='Model inputs'!B33))),'Model inputs'!B91*'Model inputs'!B22,IF('Low-price monthly forecast'!C21="","",'Low-price monthly forecast'!C21)) -> 7.84 | E6: =IF(IF(IF(ISERROR(DATE(2027,1,1)='Model inputs'!B33),DATE(2027,1,1)='Model inputs'!B33,IF('Model inputs'!B33="","",DATE(2027,1,1)='Model inputs'!B33))="",FALSE,IF(ISERROR(DATE(2027,1,1)='Model inputs'!B33),DATE(2027,1,1)='Model inputs'!B33,IF('Model inputs'!B33="","",DATE(2027,1,1)='Model inputs'!B33))),'Model inputs'!B91*'Model inputs'!B22,IF('Low-price monthly forecast'!D21="","",'Low-price monthly forecast'!D21)) -> 11.5264 | F6: =IF(IF(IF(ISERROR(DATE(2027,2,1)='Model inputs'!B33),DATE(2027,2,1)='Model inputs'!B33,IF('Model inputs'!B33="","",DATE(2027,2,1)='Model inputs'!B33))="",FALSE,IF(ISERROR(DATE(2027,2,1)='Model inputs'!B33),DATE(2027,2,1)='Model inputs'!B33,IF('Model inputs'!B33="","",DATE(2027,2,1)='Model inputs'!B33))),'Model inputs'!B91*'Model inputs'!B22,IF('Low-price monthly forecast'!E21="","",'Low-price monthly forecast'!E21)) -> 15.065344 | G6: =IF(IF(IF(ISERROR(DATE(2027,3,1)='Model inputs'!B33),DATE(2027,3,1)='Model inputs'!B33,IF('Model inputs'!B33="","",DATE(2027,3,1)='Model inputs'!B33))="",FALSE,IF(ISERROR(DATE(2027,3,1)='Model inputs'!B33),DATE(2027,3,1)='Model inputs'!B33,IF('Model inputs'!B33="","",DATE(2027,3,1)='Model inputs'!B33))),'Model inputs'!B91*'Model inputs'!B22,IF('Low-price monthly forecast'!F21="","",'Low-price monthly forecast'!F21)) -> 18.46273 | H6: =IF(IF(IF(ISERROR(DATE(2027,4,1)='Model inputs'!B33),DATE(2027,4,1)='Model inputs'!B33,IF('Model inputs'!B33="","",DATE(2027,4,1)='Model inputs'!B33))="",FALSE,IF(ISERROR(DATE(2027,4,1)='Model inputs'!B33),DATE(2027,4,1)='Model inputs'!B33,IF('Model inputs'!B33="","",DATE(2027,4,1)='Model inputs'!B33))),'Model inputs'!B91*'Model inputs'!B22,IF('Low-price monthly forecast'!G21="","",'Low-price monthly forecast'!G21)) -> 21.724221 | I6: =IF(IF(IF(ISERROR(DATE(2027,5,1)='Model inputs'!B33),DATE(2027,5,1)='Model inputs'!B33,IF('Model inputs'!B33="","",DATE(2027,5,1)='Model inputs'!B33))="",FALSE,IF(ISERROR(DATE(2027,5,1)='Model inputs'!B33),DATE(2027,5,1)='Model inputs'!B33,IF('Model inputs'!B33="","",DATE(2027,5,1)='Model inputs'!B33))),'Model inputs'!B91*'Model inputs'!B22,IF('Low-price monthly forecast'!H21="","",'Low-price monthly forecast'!H21)) -> 24.855252 | J6: =IF(IF(IF(ISERROR(DATE(2027,6,1)='Model inputs'!B33),DATE(2027,6,1)='Model inputs'!B33,IF('Model inputs'!B33="","",DATE(2027,6,1)='Model inputs'!B33))="",FALSE,IF(ISERROR(DATE(2027,6,1)='Model inputs'!B33),DATE(2027,6,1)='Model inputs'!B33,IF('Model inputs'!B33="","",DATE(2027,6,1)='Model inputs'!B33))),'Model inputs'!B91*'Model inputs'!B22,IF('Low-price monthly forecast'!I21="","",'Low-price monthly forecast'!I21)) -> 27.861042 | K6: =IF(IF(IF(ISERROR(DATE(2027,7,1)='Model inputs'!B33),DATE(2027,7,1)='Model inputs'!B33,IF('Model inputs'!B33="","",DATE(2027,7,1)='Model inputs'!B33))="",FALSE,IF(ISERROR(DATE(2027,7,1)='Model inputs'!B33),DATE(2027,7,1)='Model inputs'!B33,IF('Model inputs'!B33="","",DATE(2027,7,1)='Model inputs'!B33))),'Model inputs'!B91*'Model inputs'!B22,IF('Low-price monthly forecast'!J21="","",'Low-price monthly forecast'!J21)) -> 30.7466 | L6: =IF(IF(IF(ISERROR(DATE(2027,8,1)='Model inputs'!B33),DATE(2027,8,1)='Model inputs'!B33,IF('Model inputs'!B33="","",DATE(2027,8,1)='Model inputs'!B33))="",FALSE,IF(ISERROR(DATE(2027,8,1)='Model inputs'!B33),DATE(2027,8,1)='Model inputs'!B33,IF('Model inputs'!B33="","",DATE(2027,8,1)='Model inputs'!B33))),'Model inputs'!B91*'Model inputs'!B22,IF('Low-price monthly forecast'!K21="","",'Low-price monthly forecast'!K21)) -> 33.516736 | M6: =IF(IF(IF(ISERROR(DATE(2027,9,1)='Model inputs'!B33),DATE(2027,9,1)='Model inputs'!B33,IF('Model inputs'!B33="","",DATE(2027,9,1)='Model inputs'!B33))="",FALSE,IF(ISERROR(DATE(2027,9,1)='Model inputs'!B33),DATE(2027,9,1)='Model inputs'!B33,IF('Model inputs'!B33="","",DATE(2027,9,1)='Model inputs'!B33))),'Model inputs'!B91*'Model inputs'!B22,IF('Low-price monthly forecast'!L21="","",'Low-price monthly forecast'!L21)) -> 36.176067 | N6: =IF(IF(IF(ISERROR(DATE(2027,10,1)='Model inputs'!B33),DATE(2027,10,1)='Model inputs'!B33,IF('Model inputs'!B33="","",DATE(2027,10,1)='Model inputs'!B33))="",FALSE,IF(ISERROR(DATE(2027,10,1)='Model inputs'!B33),DATE(2027,10,1)='Model inputs'!B33,IF('Model inputs'!B33="","",DATE(2027,10,1)='Model inputs'!B33))),'Model inputs'!B91*'Model inputs'!B22,IF('Low-price monthly forecast'!M21="","",'Low-price monthly forecast'!M21)) -> 38.729024 | O6: =IF(IF(IF(ISERROR(DATE(2027,11,1)='Model inputs'!B33),DATE(2027,11,1)='Model inputs'!B33,IF('Model inputs'!B33="","",DATE(2027,11,1)='Model inputs'!B33))="",FALSE,IF(ISERROR(DATE(2027,11,1)='Model inputs'!B33),DATE(2027,11,1)='Model inputs'!B33,IF('Model inputs'!B33="","",DATE(2027,11,1)='Model inputs'!B33))),'Model inputs'!B91*'Model inputs'!B22,IF('Low-price monthly forecast'!N21="","",'Low-price monthly forecast'!N21)) -> 41.179863 | P6: =IF(IF(IF(ISERROR(DATE(2027,12,1)='Model inputs'!B33),DATE(2027,12,1)='Model inputs'!B33,IF('Model inputs'!B33="","",DATE(2027,12,1)='Model inputs'!B33))="",FALSE,IF(ISERROR(DATE(2027,12,1)='Model inputs'!B33),DATE(2027,12,1)='Model inputs'!B33,IF('Model inputs'!B33="","",DATE(2027,12,1)='Model inputs'!B33))),'Model inputs'!B91*'Model inputs'!B22,IF('Low-price monthly forecast'!O21="","",'Low-price monthly forecast'!O21)) -> 43.532669 | Q6: =IF(IF(IF(ISERROR(DATE(2028,1,1)='Model inputs'!B33),DATE(2028,1,1)='Model inputs'!B33,IF('Model inputs'!B33="","",DATE(2028,1,1)='Model inputs'!B33))="",FALSE,IF(ISERROR(DATE(2028,1,1)='Model inputs'!B33),DATE(2028,1,1)='Model inputs'!B33,IF('Model inputs'!B33="","",DATE(2028,1,1)='Model inputs'!B33))),'Model inputs'!B91*'Model inputs'!B22,IF('Low-price monthly forecast'!P21="","",'Low-price monthly forecast'!P21)) -> 45.791362 | R6: =IF(IF(IF(ISERROR(DATE(2028,2,1)='Model inputs'!B33),DATE(2028,2,1)='Model inputs'!B33,IF('Model inputs'!B33="","",DATE(2028,2,1)='Model inputs'!B33))="",FALSE,IF(ISERROR(DATE(2028,2,1)='Model inputs'!B33),DATE(2028,2,1)='Model inputs'!B33,IF('Model inputs'!B33="","",DATE(2028,2,1)='Model inputs'!B33))),'Model inputs'!B91*'Model inputs'!B22,IF('Low-price monthly forecast'!Q21="","",'Low-price monthly forecast'!Q21)) -> 47.959708 | S6: =IF(IF(IF(ISERROR(DATE(2028,3,1)='Model inputs'!B33),DATE(2028,3,1)='Model inputs'!B33,IF('Model inputs'!B33="","",DATE(2028,3,1)='Model inputs'!B33))="",FALSE,IF(ISERROR(DATE(2028,3,1)='Model inputs'!B33),DATE(2028,3,1)='Model inputs'!B33,IF('Model inputs'!B33="","",DATE(2028,3,1)='Model inputs'!B33))),'Model inputs'!B91*'Model inputs'!B22,IF('Low-price monthly forecast'!R21="","",'Low-price monthly forecast'!R21)) -> 50.041319
A7: Community | B7: =IF(IF(IF(ISERROR(DATE(2026,10,1)='Model inputs'!B33),DATE(2026,10,1)='Model inputs'!B33,IF('Model inputs'!B33="","",DATE(2026,10,1)='Model inputs'!B33))="",FALSE,IF(ISERROR(DATE(2026,10,1)='Model inputs'!B33),DATE(2026,10,1)='Model inputs'!B33,IF('Model inputs'!B33="","",DATE(2026,10,1)='Model inputs'!B33))),'Model inputs'!B91*'Model inputs'!B23,IF('Model inputs'!K79="","",'Model inputs'!K79)) -> 0 | C7: =IF(IF(IF(ISERROR(DATE(2026,11,1)='Model inputs'!B33),DATE(2026,11,1)='Model inputs'!B33,IF('Model inputs'!B33="","",DATE(2026,11,1)='Model inputs'!B33))="",FALSE,IF(ISERROR(DATE(2026,11,1)='Model inputs'!B33),DATE(2026,11,1)='Model inputs'!B33,IF('Model inputs'!B33="","",DATE(2026,11,1)='Model inputs'!B33))),'Model inputs'!B91*'Model inputs'!B23,IF('Low-price monthly forecast'!B22="","",'Low-price monthly forecast'!B22)) -> 0 | D7: =IF(IF(IF(ISERROR(DATE(2026,12,1)='Model inputs'!B33),DATE(2026,12,1)='Model inputs'!B33,IF('Model inputs'!B33="","",DATE(2026,12,1)='Model inputs'!B33))="",FALSE,IF(ISERROR(DATE(2026,12,1)='Model inputs'!B33),DATE(2026,12,1)='Model inputs'!B33,IF('Model inputs'!B33="","",DATE(2026,12,1)='Model inputs'!B33))),'Model inputs'!B91*'Model inputs'!B23,IF('Low-price monthly forecast'!C22="","",'Low-price monthly forecast'!C22)) -> 0 | E7: =IF(IF(IF(ISERROR(DATE(2027,1,1)='Model inputs'!B33),DATE(2027,1,1)='Model inputs'!B33,IF('Model inputs'!B33="","",DATE(2027,1,1)='Model inputs'!B33))="",FALSE,IF(ISERROR(DATE(2027,1,1)='Model inputs'!B33),DATE(2027,1,1)='Model inputs'!B33,IF('Model inputs'!B33="","",DATE(2027,1,1)='Model inputs'!B33))),'Model inputs'!B91*'Model inputs'!B23,IF('Low-price monthly forecast'!D22="","",'Low-price monthly forecast'!D22)) -> 0 | F7: =IF(IF(IF(ISERROR(DATE(2027,2,1)='Model inputs'!B33),DATE(2027,2,1)='Model inputs'!B33,IF('Model inputs'!B33="","",DATE(2027,2,1)='Model inputs'!B33))="",FALSE,IF(ISERROR(DATE(2027,2,1)='Model inputs'!B33),DATE(2027,2,1)='Model inputs'!B33,IF('Model inputs'!B33="","",DATE(2027,2,1)='Model inputs'!B33))),'Model inputs'!B91*'Model inputs'!B23,IF('Low-price monthly forecast'!E22="","",'Low-price monthly forecast'!E22)) -> 0 | G7: =IF(IF(IF(ISERROR(DATE(2027,3,1)='Model inputs'!B33),DATE(2027,3,1)='Model inputs'!B33,IF('Model inputs'!B33="","",DATE(2027,3,1)='Model inputs'!B33))="",FALSE,IF(ISERROR(DATE(2027,3,1)='Model inputs'!B33),DATE(2027,3,1)='Model inputs'!B33,IF('Model inputs'!B33="","",DATE(2027,3,1)='Model inputs'!B33))),'Model inputs'!B91*'Model inputs'!B23,IF('Low-price monthly forecast'!F22="","",'Low-price monthly forecast'!F22)) -> 0 | H7: =IF(IF(IF(ISERROR(DATE(2027,4,1)='Model inputs'!B33),DATE(2027,4,1)='Model inputs'!B33,IF('Model inputs'!B33="","",DATE(2027,4,1)='Model inputs'!B33))="",FALSE,IF(ISERROR(DATE(2027,4,1)='Model inputs'!B33),DATE(2027,4,1)='Model inputs'!B33,IF('Model inputs'!B33="","",DATE(2027,4,1)='Model inputs'!B33))),'Model inputs'!B91*'Model inputs'!B23,IF('Low-price monthly forecast'!G22="","",'Low-price monthly forecast'!G22)) -> 0 | I7: =IF(IF(IF(ISERROR(DATE(2027,5,1)='Model inputs'!B33),DATE(2027,5,1)='Model inputs'!B33,IF('Model inputs'!B33="","",DATE(2027,5,1)='Model inputs'!B33))="",FALSE,IF(ISERROR(DATE(2027,5,1)='Model inputs'!B33),DATE(2027,5,1)='Model inputs'!B33,IF('Model inputs'!B33="","",DATE(2027,5,1)='Model inputs'!B33))),'Model inputs'!B91*'Model inputs'!B23,IF('Low-price monthly forecast'!H22="","",'Low-price monthly forecast'!H22)) -> 0 | J7: =IF(IF(IF(ISERROR(DATE(2027,6,1)='Model inputs'!B33),DATE(2027,6,1)='Model inputs'!B33,IF('Model inputs'!B33="","",DATE(2027,6,1)='Model inputs'!B33))="",FALSE,IF(ISERROR(DATE(2027,6,1)='Model inputs'!B33),DATE(2027,6,1)='Model inputs'!B33,IF('Model inputs'!B33="","",DATE(2027,6,1)='Model inputs'!B33))),'Model inputs'!B91*'Model inputs'!B23,IF('Low-price monthly forecast'!I22="","",'Low-price monthly forecast'!I22)) -> 0 | K7: =IF(IF(IF(ISERROR(DATE(2027,7,1)='Model inputs'!B33),DATE(2027,7,1)='Model inputs'!B33,IF('Model inputs'!B33="","",DATE(2027,7,1)='Model inputs'!B33))="",FALSE,IF(ISERROR(DATE(2027,7,1)='Model inputs'!B33),DATE(2027,7,1)='Model inputs'!B33,IF('Model inputs'!B33="","",DATE(2027,7,1)='Model inputs'!B33))),'Model inputs'!B91*'Model inputs'!B23,IF('Low-price monthly forecast'!J22="","",'Low-price monthly forecast'!J22)) -> 0 | L7: =IF(IF(IF(ISERROR(DATE(2027,8,1)='Model inputs'!B33),DATE(2027,8,1)='Model inputs'!B33,IF('Model inputs'!B33="","",DATE(2027,8,1)='Model inputs'!B33))="",FALSE,IF(ISERROR(DATE(2027,8,1)='Model inputs'!B33),DATE(2027,8,1)='Model inputs'!B33,IF('Model inputs'!B33="","",DATE(2027,8,1)='Model inputs'!B33))),'Model inputs'!B91*'Model inputs'!B23,IF('Low-price monthly forecast'!K22="","",'Low-price monthly forecast'!K22)) -> 0 | M7: =IF(IF(IF(ISERROR(DATE(2027,9,1)='Model inputs'!B33),DATE(2027,9,1)='Model inputs'!B33,IF('Model inputs'!B33="","",DATE(2027,9,1)='Model inputs'!B33))="",FALSE,IF(ISERROR(DATE(2027,9,1)='Model inputs'!B33),DATE(2027,9,1)='Model inputs'!B33,IF('Model inputs'!B33="","",DATE(2027,9,1)='Model inputs'!B33))),'Model inputs'!B91*'Model inputs'!B23,IF('Low-price monthly forecast'!L22="","",'Low-price monthly forecast'!L22)) -> 0 | N7: =IF(IF(IF(ISERROR(DATE(2027,10,1)='Model inputs'!B33),DATE(2027,10,1)='Model inputs'!B33,IF('Model inputs'!B33="","",DATE(2027,10,1)='Model inputs'!B33))="",FALSE,IF(ISERROR(DATE(2027,10,1)='Model inputs'!B33),DATE(2027,10,1)='Model inputs'!B33,IF('Model inputs'!B33="","",DATE(2027,10,1)='Model inputs'!B33))),'Model inputs'!B91*'Model inputs'!B23,IF('Low-price monthly forecast'!M22="","",'Low-price monthly forecast'!M22)) -> 0 | O7: =IF(IF(IF(ISERROR(DATE(2027,11,1)='Model inputs'!B33),DATE(2027,11,1)='Model inputs'!B33,IF('Model inputs'!B33="","",DATE(2027,11,1)='Model inputs'!B33))="",FALSE,IF(ISERROR(DATE(2027,11,1)='Model inputs'!B33),DATE(2027,11,1)='Model inputs'!B33,IF('Model inputs'!B33="","",DATE(2027,11,1)='Model inputs'!B33))),'Model inputs'!B91*'Model inputs'!B23,IF('Low-price monthly forecast'!N22="","",'Low-price monthly forecast'!N22)) -> 0 | P7: =IF(IF(IF(ISERROR(DATE(2027,12,1)='Model inputs'!B33),DATE(2027,12,1)='Model inputs'!B33,IF('Model inputs'!B33="","",DATE(2027,12,1)='Model inputs'!B33))="",FALSE,IF(ISERROR(DATE(2027,12,1)='Model inputs'!B33),DATE(2027,12,1)='Model inputs'!B33,IF('Model inputs'!B33="","",DATE(2027,12,1)='Model inputs'!B33))),'Model inputs'!B91*'Model inputs'!B23,IF('Low-price monthly forecast'!O22="","",'Low-price monthly forecast'!O22)) -> 0 | Q7: =IF(IF(IF(ISERROR(DATE(2028,1,1)='Model inputs'!B33),DATE(2028,1,1)='Model inputs'!B33,IF('Model inputs'!B33="","",DATE(2028,1,1)='Model inputs'!B33))="",FALSE,IF(ISERROR(DATE(2028,1,1)='Model inputs'!B33),DATE(2028,1,1)='Model inputs'!B33,IF('Model inputs'!B33="","",DATE(2028,1,1)='Model inputs'!B33))),'Model inputs'!B91*'Model inputs'!B23,IF('Low-price monthly forecast'!P22="","",'Low-price monthly forecast'!P22)) -> 0 | R7: =IF(IF(IF(ISERROR(DATE(2028,2,1)='Model inputs'!B33),DATE(2028,2,1)='Model inputs'!B33,IF('Model inputs'!B33="","",DATE(2028,2,1)='Model inputs'!B33))="",FALSE,IF(ISERROR(DATE(2028,2,1)='Model inputs'!B33),DATE(2028,2,1)='Model inputs'!B33,IF('Model inputs'!B33="","",DATE(2028,2,1)='Model inputs'!B33))),'Model inputs'!B91*'Model inputs'!B23,IF('Low-price monthly forecast'!Q22="","",'Low-price monthly forecast'!Q22)) -> 0 | S7: =IF(IF(IF(ISERROR(DATE(2028,3,1)='Model inputs'!B33),DATE(2028,3,1)='Model inputs'!B33,IF('Model inputs'!B33="","",DATE(2028,3,1)='Model inputs'!B33))="",FALSE,IF(ISERROR(DATE(2028,3,1)='Model inputs'!B33),DATE(2028,3,1)='Model inputs'!B33,IF('Model inputs'!B33="","",DATE(2028,3,1)='Model inputs'!B33))),'Model inputs'!B91*'Model inputs'!B23,IF('Low-price monthly forecast'!R22="","",'Low-price monthly forecast'!R22)) -> 0
A8: Starter | B8: =IF(IF(IF(ISERROR(DATE(2026,10,1)='Model inputs'!B33),DATE(2026,10,1)='Model inputs'!B33,IF('Model inputs'!B33="","",DATE(2026,10,1)='Model inputs'!B33))="",FALSE,IF(ISERROR(DATE(2026,10,1)='Model inputs'!B33),DATE(2026,10,1)='Model inputs'!B33,IF('Model inputs'!B33="","",DATE(2026,10,1)='Model inputs'!B33))),'Model inputs'!B91*'Model inputs'!B24,IF('Model inputs'!K80="","",'Model inputs'!K80)) -> 0 | C8: =IF(IF(IF(ISERROR(DATE(2026,11,1)='Model inputs'!B33),DATE(2026,11,1)='Model inputs'!B33,IF('Model inputs'!B33="","",DATE(2026,11,1)='Model inputs'!B33))="",FALSE,IF(ISERROR(DATE(2026,11,1)='Model inputs'!B33),DATE(2026,11,1)='Model inputs'!B33,IF('Model inputs'!B33="","",DATE(2026,11,1)='Model inputs'!B33))),'Model inputs'!B91*'Model inputs'!B24,IF('Low-price monthly forecast'!B23="","",'Low-price monthly forecast'!B23)) -> 22 | D8: =IF(IF(IF(ISERROR(DATE(2026,12,1)='Model inputs'!B33),DATE(2026,12,1)='Model inputs'!B33,IF('Model inputs'!B33="","",DATE(2026,12,1)='Model inputs'!B33))="",FALSE,IF(ISERROR(DATE(2026,12,1)='Model inputs'!B33),DATE(2026,12,1)='Model inputs'!B33,IF('Model inputs'!B33="","",DATE(2026,12,1)='Model inputs'!B33))),'Model inputs'!B91*'Model inputs'!B24,IF('Low-price monthly forecast'!C23="","",'Low-price monthly forecast'!C23)) -> 43.12 | E8: =IF(IF(IF(ISERROR(DATE(2027,1,1)='Model inputs'!B33),DATE(2027,1,1)='Model inputs'!B33,IF('Model inputs'!B33="","",DATE(2027,1,1)='Model inputs'!B33))="",FALSE,IF(ISERROR(DATE(2027,1,1)='Model inputs'!B33),DATE(2027,1,1)='Model inputs'!B33,IF('Model inputs'!B33="","",DATE(2027,1,1)='Model inputs'!B33))),'Model inputs'!B91*'Model inputs'!B24,IF('Low-price monthly forecast'!D23="","",'Low-price monthly forecast'!D23)) -> 63.3952 | F8: =IF(IF(IF(ISERROR(DATE(2027,2,1)='Model inputs'!B33),DATE(2027,2,1)='Model inputs'!B33,IF('Model inputs'!B33="","",DATE(2027,2,1)='Model inputs'!B33))="",FALSE,IF(ISERROR(DATE(2027,2,1)='Model inputs'!B33),DATE(2027,2,1)='Model inputs'!B33,IF('Model inputs'!B33="","",DATE(2027,2,1)='Model inputs'!B33))),'Model inputs'!B91*'Model inputs'!B24,IF('Low-price monthly forecast'!E23="","",'Low-price monthly forecast'!E23)) -> 82.859392 | G8: =IF(IF(IF(ISERROR(DATE(2027,3,1)='Model inputs'!B33),DATE(2027,3,1)='Model inputs'!B33,IF('Model inputs'!B33="","",DATE(2027,3,1)='Model inputs'!B33))="",FALSE,IF(ISERROR(DATE(2027,3,1)='Model inputs'!B33),DATE(2027,3,1)='Model inputs'!B33,IF('Model inputs'!B33="","",DATE(2027,3,1)='Model inputs'!B33))),'Model inputs'!B91*'Model inputs'!B24,IF('Low-price monthly forecast'!F23="","",'Low-price monthly forecast'!F23)) -> 101.54502 | H8: =IF(IF(IF(ISERROR(DATE(2027,4,1)='Model inputs'!B33),DATE(2027,4,1)='Model inputs'!B33,IF('Model inputs'!B33="","",DATE(2027,4,1)='Model inputs'!B33))="",FALSE,IF(ISERROR(DATE(2027,4,1)='Model inputs'!B33),DATE(2027,4,1)='Model inputs'!B33,IF('Model inputs'!B33="","",DATE(2027,4,1)='Model inputs'!B33))),'Model inputs'!B91*'Model inputs'!B24,IF('Low-price monthly forecast'!G23="","",'Low-price monthly forecast'!G23)) -> 119.48322 | I8: =IF(IF(IF(ISERROR(DATE(2027,5,1)='Model inputs'!B33),DATE(2027,5,1)='Model inputs'!B33,IF('Model inputs'!B33="","",DATE(2027,5,1)='Model inputs'!B33))="",FALSE,IF(ISERROR(DATE(2027,5,1)='Model inputs'!B33),DATE(2027,5,1)='Model inputs'!B33,IF('Model inputs'!B33="","",DATE(2027,5,1)='Model inputs'!B33))),'Model inputs'!B91*'Model inputs'!B24,IF('Low-price monthly forecast'!H23="","",'Low-price monthly forecast'!H23)) -> 136.70389 | J8: =IF(IF(IF(ISERROR(DATE(2027,6,1)='Model inputs'!B33),DATE(2027,6,1)='Model inputs'!B33,IF('Model inputs'!B33="","",DATE(2027,6,1)='Model inputs'!B33))="",FALSE,IF(ISERROR(DATE(2027,6,1)='Model inputs'!B33),DATE(2027,6,1)='Model inputs'!B33,IF('Model inputs'!B33="","",DATE(2027,6,1)='Model inputs'!B33))),'Model inputs'!B91*'Model inputs'!B24,IF('Low-price monthly forecast'!I23="","",'Low-price monthly forecast'!I23)) -> 153.23573 | K8: =IF(IF(IF(ISERROR(DATE(2027,7,1)='Model inputs'!B33),DATE(2027,7,1)='Model inputs'!B33,IF('Model inputs'!B33="","",DATE(2027,7,1)='Model inputs'!B33))="",FALSE,IF(ISERROR(DATE(2027,7,1)='Model inputs'!B33),DATE(2027,7,1)='Model inputs'!B33,IF('Model inputs'!B33="","",DATE(2027,7,1)='Model inputs'!B33))),'Model inputs'!B91*'Model inputs'!B24,IF('Low-price monthly forecast'!J23="","",'Low-price monthly forecast'!J23)) -> 169.1063 | L8: =IF(IF(IF(ISERROR(DATE(2027,8,1)='Model inputs'!B33),DATE(2027,8,1)='Model inputs'!B33,IF('Model inputs'!B33="","",DATE(2027,8,1)='Model inputs'!B33))="",FALSE,IF(ISERROR(DATE(2027,8,1)='Model inputs'!B33),DATE(2027,8,1)='Model inputs'!B33,IF('Model inputs'!B33="","",DATE(2027,8,1)='Model inputs'!B33))),'Model inputs'!B91*'Model inputs'!B24,IF('Low-price monthly forecast'!K23="","",'Low-price monthly forecast'!K23)) -> 184.34205 | M8: =IF(IF(IF(ISERROR(DATE(2027,9,1)='Model inputs'!B33),DATE(2027,9,1)='Model inputs'!B33,IF('Model inputs'!B33="","",DATE(2027,9,1)='Model inputs'!B33))="",FALSE,IF(ISERROR(DATE(2027,9,1)='Model inputs'!B33),DATE(2027,9,1)='Model inputs'!B33,IF('Model inputs'!B33="","",DATE(2027,9,1)='Model inputs'!B33))),'Model inputs'!B91*'Model inputs'!B24,IF('Low-price monthly forecast'!L23="","",'Low-price monthly forecast'!L23)) -> 198.96837 | N8: =IF(IF(IF(ISERROR(DATE(2027,10,1)='Model inputs'!B33),DATE(2027,10,1)='Model inputs'!B33,IF('Model inputs'!B33="","",DATE(2027,10,1)='Model inputs'!B33))="",FALSE,IF(ISERROR(DATE(2027,10,1)='Model inputs'!B33),DATE(2027,10,1)='Model inputs'!B33,IF('Model inputs'!B33="","",DATE(2027,10,1)='Model inputs'!B33))),'Model inputs'!B91*'Model inputs'!B24,IF('Low-price monthly forecast'!M23="","",'Low-price monthly forecast'!M23)) -> 213.00963 | O8: =IF(IF(IF(ISERROR(DATE(2027,11,1)='Model inputs'!B33),DATE(2027,11,1)='Model inputs'!B33,IF('Model inputs'!B33="","",DATE(2027,11,1)='Model inputs'!B33))="",FALSE,IF(ISERROR(DATE(2027,11,1)='Model inputs'!B33),DATE(2027,11,1)='Model inputs'!B33,IF('Model inputs'!B33="","",DATE(2027,11,1)='Model inputs'!B33))),'Model inputs'!B91*'Model inputs'!B24,IF('Low-price monthly forecast'!N23="","",'Low-price monthly forecast'!N23)) -> 226.48925 | P8: =IF(IF(IF(ISERROR(DATE(2027,12,1)='Model inputs'!B33),DATE(2027,12,1)='Model inputs'!B33,IF('Model inputs'!B33="","",DATE(2027,12,1)='Model inputs'!B33))="",FALSE,IF(ISERROR(DATE(2027,12,1)='Model inputs'!B33),DATE(2027,12,1)='Model inputs'!B33,IF('Model inputs'!B33="","",DATE(2027,12,1)='Model inputs'!B33))),'Model inputs'!B91*'Model inputs'!B24,IF('Low-price monthly forecast'!O23="","",'Low-price monthly forecast'!O23)) -> 239.42968 | Q8: =IF(IF(IF(ISERROR(DATE(2028,1,1)='Model inputs'!B33),DATE(2028,1,1)='Model inputs'!B33,IF('Model inputs'!B33="","",DATE(2028,1,1)='Model inputs'!B33))="",FALSE,IF(ISERROR(DATE(2028,1,1)='Model inputs'!B33),DATE(2028,1,1)='Model inputs'!B33,IF('Model inputs'!B33="","",DATE(2028,1,1)='Model inputs'!B33))),'Model inputs'!B91*'Model inputs'!B24,IF('Low-price monthly forecast'!P23="","",'Low-price monthly forecast'!P23)) -> 251.85249 | R8: =IF(IF(IF(ISERROR(DATE(2028,2,1)='Model inputs'!B33),DATE(2028,2,1)='Model inputs'!B33,IF('Model inputs'!B33="","",DATE(2028,2,1)='Model inputs'!B33))="",FALSE,IF(ISERROR(DATE(2028,2,1)='Model inputs'!B33),DATE(2028,2,1)='Model inputs'!B33,IF('Model inputs'!B33="","",DATE(2028,2,1)='Model inputs'!B33))),'Model inputs'!B91*'Model inputs'!B24,IF('Low-price monthly forecast'!Q23="","",'Low-price monthly forecast'!Q23)) -> 263.77839 | S8: =IF(IF(IF(ISERROR(DATE(2028,3,1)='Model inputs'!B33),DATE(2028,3,1)='Model inputs'!B33,IF('Model inputs'!B33="","",DATE(2028,3,1)='Model inputs'!B33))="",FALSE,IF(ISERROR(DATE(2028,3,1)='Model inputs'!B33),DATE(2028,3,1)='Model inputs'!B33,IF('Model inputs'!B33="","",DATE(2028,3,1)='Model inputs'!B33))),'Model inputs'!B91*'Model inputs'!B24,IF('Low-price monthly forecast'!R23="","",'Low-price monthly forecast'!R23)) -> 275.22726
A9: Team | B9: =IF(IF(IF(ISERROR(DATE(2026,10,1)='Model inputs'!B33),DATE(2026,10,1)='Model inputs'!B33,IF('Model inputs'!B33="","",DATE(2026,10,1)='Model inputs'!B33))="",FALSE,IF(ISERROR(DATE(2026,10,1)='Model inputs'!B33),DATE(2026,10,1)='Model inputs'!B33,IF('Model inputs'!B33="","",DATE(2026,10,1)='Model inputs'!B33))),'Model inputs'!B91*'Model inputs'!B25,IF('Model inputs'!K81="","",'Model inputs'!K81)) -> 0 | C9: =IF(IF(IF(ISERROR(DATE(2026,11,1)='Model inputs'!B33),DATE(2026,11,1)='Model inputs'!B33,IF('Model inputs'!B33="","",DATE(2026,11,1)='Model inputs'!B33))="",FALSE,IF(ISERROR(DATE(2026,11,1)='Model inputs'!B33),DATE(2026,11,1)='Model inputs'!B33,IF('Model inputs'!B33="","",DATE(2026,11,1)='Model inputs'!B33))),'Model inputs'!B91*'Model inputs'!B25,IF('Low-price monthly forecast'!B24="","",'Low-price monthly forecast'!B24)) -> 14 | D9: =IF(IF(IF(ISERROR(DATE(2026,12,1)='Model inputs'!B33),DATE(2026,12,1)='Model inputs'!B33,IF('Model inputs'!B33="","",DATE(2026,12,1)='Model inputs'!B33))="",FALSE,IF(ISERROR(DATE(2026,12,1)='Model inputs'!B33),DATE(2026,12,1)='Model inputs'!B33,IF('Model inputs'!B33="","",DATE(2026,12,1)='Model inputs'!B33))),'Model inputs'!B91*'Model inputs'!B25,IF('Low-price monthly forecast'!C24="","",'Low-price monthly forecast'!C24)) -> 27.44 | E9: =IF(IF(IF(ISERROR(DATE(2027,1,1)='Model inputs'!B33),DATE(2027,1,1)='Model inputs'!B33,IF('Model inputs'!B33="","",DATE(2027,1,1)='Model inputs'!B33))="",FALSE,IF(ISERROR(DATE(2027,1,1)='Model inputs'!B33),DATE(2027,1,1)='Model inputs'!B33,IF('Model inputs'!B33="","",DATE(2027,1,1)='Model inputs'!B33))),'Model inputs'!B91*'Model inputs'!B25,IF('Low-price monthly forecast'!D24="","",'Low-price monthly forecast'!D24)) -> 40.3424 | F9: =IF(IF(IF(ISERROR(DATE(2027,2,1)='Model inputs'!B33),DATE(2027,2,1)='Model inputs'!B33,IF('Model inputs'!B33="","",DATE(2027,2,1)='Model inputs'!B33))="",FALSE,IF(ISERROR(DATE(2027,2,1)='Model inputs'!B33),DATE(2027,2,1)='Model inputs'!B33,IF('Model inputs'!B33="","",DATE(2027,2,1)='Model inputs'!B33))),'Model inputs'!B91*'Model inputs'!B25,IF('Low-price monthly forecast'!E24="","",'Low-price monthly forecast'!E24)) -> 52.728704 | G9: =IF(IF(IF(ISERROR(DATE(2027,3,1)='Model inputs'!B33),DATE(2027,3,1)='Model inputs'!B33,IF('Model inputs'!B33="","",DATE(2027,3,1)='Model inputs'!B33))="",FALSE,IF(ISERROR(DATE(2027,3,1)='Model inputs'!B33),DATE(2027,3,1)='Model inputs'!B33,IF('Model inputs'!B33="","",DATE(2027,3,1)='Model inputs'!B33))),'Model inputs'!B91*'Model inputs'!B25,IF('Low-price monthly forecast'!F24="","",'Low-price monthly forecast'!F24)) -> 64.619556 | H9: =IF(IF(IF(ISERROR(DATE(2027,4,1)='Model inputs'!B33),DATE(2027,4,1)='Model inputs'!B33,IF('Model inputs'!B33="","",DATE(2027,4,1)='Model inputs'!B33))="",FALSE,IF(ISERROR(DATE(2027,4,1)='Model inputs'!B33),DATE(2027,4,1)='Model inputs'!B33,IF('Model inputs'!B33="","",DATE(2027,4,1)='Model inputs'!B33))),'Model inputs'!B91*'Model inputs'!B25,IF('Low-price monthly forecast'!G24="","",'Low-price monthly forecast'!G24)) -> 76.034774 | I9: =IF(IF(IF(ISERROR(DATE(2027,5,1)='Model inputs'!B33),DATE(2027,5,1)='Model inputs'!B33,IF('Model inputs'!B33="","",DATE(2027,5,1)='Model inputs'!B33))="",FALSE,IF(ISERROR(DATE(2027,5,1)='Model inputs'!B33),DATE(2027,5,1)='Model inputs'!B33,IF('Model inputs'!B33="","",DATE(2027,5,1)='Model inputs'!B33))),'Model inputs'!B91*'Model inputs'!B25,IF('Low-price monthly forecast'!H24="","",'Low-price monthly forecast'!H24)) -> 86.993383 | J9: =IF(IF(IF(ISERROR(DATE(2027,6,1)='Model inputs'!B33),DATE(2027,6,1)='Model inputs'!B33,IF('Model inputs'!B33="","",DATE(2027,6,1)='Model inputs'!B33))="",FALSE,IF(ISERROR(DATE(2027,6,1)='Model inputs'!B33),DATE(2027,6,1)='Model inputs'!B33,IF('Model inputs'!B33="","",DATE(2027,6,1)='Model inputs'!B33))),'Model inputs'!B91*'Model inputs'!B25,IF('Low-price monthly forecast'!I24="","",'Low-price monthly forecast'!I24)) -> 97.513647 | K9: =IF(IF(IF(ISERROR(DATE(2027,7,1)='Model inputs'!B33),DATE(2027,7,1)='Model inputs'!B33,IF('Model inputs'!B33="","",DATE(2027,7,1)='Model inputs'!B33))="",FALSE,IF(ISERROR(DATE(2027,7,1)='Model inputs'!B33),DATE(2027,7,1)='Model inputs'!B33,IF('Model inputs'!B33="","",DATE(2027,7,1)='Model inputs'!B33))),'Model inputs'!B91*'Model inputs'!B25,IF('Low-price monthly forecast'!J24="","",'Low-price monthly forecast'!J24)) -> 107.6131 | L9: =IF(IF(IF(ISERROR(DATE(2027,8,1)='Model inputs'!B33),DATE(2027,8,1)='Model inputs'!B33,IF('Model inputs'!B33="","",DATE(2027,8,1)='Model inputs'!B33))="",FALSE,IF(ISERROR(DATE(2027,8,1)='Model inputs'!B33),DATE(2027,8,1)='Model inputs'!B33,IF('Model inputs'!B33="","",DATE(2027,8,1)='Model inputs'!B33))),'Model inputs'!B91*'Model inputs'!B25,IF('Low-price monthly forecast'!K24="","",'Low-price monthly forecast'!K24)) -> 117.30858 | M9: =IF(IF(IF(ISERROR(DATE(2027,9,1)='Model inputs'!B33),DATE(2027,9,1)='Model inputs'!B33,IF('Model inputs'!B33="","",DATE(2027,9,1)='Model inputs'!B33))="",FALSE,IF(ISERROR(DATE(2027,9,1)='Model inputs'!B33),DATE(2027,9,1)='Model inputs'!B33,IF('Model inputs'!B33="","",DATE(2027,9,1)='Model inputs'!B33))),'Model inputs'!B91*'Model inputs'!B25,IF('Low-price monthly forecast'!L24="","",'Low-price monthly forecast'!L24)) -> 126.61623 | N9: =IF(IF(IF(ISERROR(DATE(2027,10,1)='Model inputs'!B33),DATE(2027,10,1)='Model inputs'!B33,IF('Model inputs'!B33="","",DATE(2027,10,1)='Model inputs'!B33))="",FALSE,IF(ISERROR(DATE(2027,10,1)='Model inputs'!B33),DATE(2027,10,1)='Model inputs'!B33,IF('Model inputs'!B33="","",DATE(2027,10,1)='Model inputs'!B33))),'Model inputs'!B91*'Model inputs'!B25,IF('Low-price monthly forecast'!M24="","",'Low-price monthly forecast'!M24)) -> 135.55158 | O9: =IF(IF(IF(ISERROR(DATE(2027,11,1)='Model inputs'!B33),DATE(2027,11,1)='Model inputs'!B33,IF('Model inputs'!B33="","",DATE(2027,11,1)='Model inputs'!B33))="",FALSE,IF(ISERROR(DATE(2027,11,1)='Model inputs'!B33),DATE(2027,11,1)='Model inputs'!B33,IF('Model inputs'!B33="","",DATE(2027,11,1)='Model inputs'!B33))),'Model inputs'!B91*'Model inputs'!B25,IF('Low-price monthly forecast'!N24="","",'Low-price monthly forecast'!N24)) -> 144.12952 | P9: =IF(IF(IF(ISERROR(DATE(2027,12,1)='Model inputs'!B33),DATE(2027,12,1)='Model inputs'!B33,IF('Model inputs'!B33="","",DATE(2027,12,1)='Model inputs'!B33))="",FALSE,IF(ISERROR(DATE(2027,12,1)='Model inputs'!B33),DATE(2027,12,1)='Model inputs'!B33,IF('Model inputs'!B33="","",DATE(2027,12,1)='Model inputs'!B33))),'Model inputs'!B91*'Model inputs'!B25,IF('Low-price monthly forecast'!O24="","",'Low-price monthly forecast'!O24)) -> 152.36434 | Q9: =IF(IF(IF(ISERROR(DATE(2028,1,1)='Model inputs'!B33),DATE(2028,1,1)='Model inputs'!B33,IF('Model inputs'!B33="","",DATE(2028,1,1)='Model inputs'!B33))="",FALSE,IF(ISERROR(DATE(2028,1,1)='Model inputs'!B33),DATE(2028,1,1)='Model inputs'!B33,IF('Model inputs'!B33="","",DATE(2028,1,1)='Model inputs'!B33))),'Model inputs'!B91*'Model inputs'!B25,IF('Low-price monthly forecast'!P24="","",'Low-price monthly forecast'!P24)) -> 160.26977 | R9: =IF(IF(IF(ISERROR(DATE(2028,2,1)='Model inputs'!B33),DATE(2028,2,1)='Model inputs'!B33,IF('Model inputs'!B33="","",DATE(2028,2,1)='Model inputs'!B33))="",FALSE,IF(ISERROR(DATE(2028,2,1)='Model inputs'!B33),DATE(2028,2,1)='Model inputs'!B33,IF('Model inputs'!B33="","",DATE(2028,2,1)='Model inputs'!B33))),'Model inputs'!B91*'Model inputs'!B25,IF('Low-price monthly forecast'!Q24="","",'Low-price monthly forecast'!Q24)) -> 167.85898 | S9: =IF(IF(IF(ISERROR(DATE(2028,3,1)='Model inputs'!B33),DATE(2028,3,1)='Model inputs'!B33,IF('Model inputs'!B33="","",DATE(2028,3,1)='Model inputs'!B33))="",FALSE,IF(ISERROR(DATE(2028,3,1)='Model inputs'!B33),DATE(2028,3,1)='Model inputs'!B33,IF('Model inputs'!B33="","",DATE(2028,3,1)='Model inputs'!B33))),'Model inputs'!B91*'Model inputs'!B25,IF('Low-price monthly forecast'!R24="","",'Low-price monthly forecast'!R24)) -> 175.14462
A10: NW New customers | B10: =SUM('Low-price monthly forecast'!B11,'Low-price monthly forecast'!B12,'Low-price monthly forecast'!B13,'Low-price monthly forecast'!B14) -> 40 | C10: =SUM('Low-price monthly forecast'!C11,'Low-price monthly forecast'!C12,'Low-price monthly forecast'!C13,'Low-price monthly forecast'!C14) -> 40 | D10: =SUM('Low-price monthly forecast'!D11,'Low-price monthly forecast'!D12,'Low-price monthly forecast'!D13,'Low-price monthly forecast'!D14) -> 40 | E10: =SUM('Low-price monthly forecast'!E11,'Low-price monthly forecast'!E12,'Low-price monthly forecast'!E13,'Low-price monthly forecast'!E14) -> 40 | F10: =SUM('Low-price monthly forecast'!F11,'Low-price monthly forecast'!F12,'Low-price monthly forecast'!F13,'Low-price monthly forecast'!F14) -> 40 | G10: =SUM('Low-price monthly forecast'!G11,'Low-price monthly forecast'!G12,'Low-price monthly forecast'!G13,'Low-price monthly forecast'!G14) -> 40 | H10: =SUM('Low-price monthly forecast'!H11,'Low-price monthly forecast'!H12,'Low-price monthly forecast'!H13,'Low-price monthly forecast'!H14) -> 40 | I10: =SUM('Low-price monthly forecast'!I11,'Low-price monthly forecast'!I12,'Low-price monthly forecast'!I13,'Low-price monthly forecast'!I14) -> 40 | ... S10: =SUM('Low-price monthly forecast'!S11,'Low-price monthly forecast'!S12,'Low-price monthly forecast'!S13,'Low-price monthly forecast'!S14) -> 40
A11: Business | B11: ='Model inputs'!B65*'Model inputs'!B22 -> 4 | C11: ='Model inputs'!B65*'Model inputs'!B22 -> 4 | D11: ='Model inputs'!B65*'Model inputs'!B22 -> 4 | E11: ='Model inputs'!B65*'Model inputs'!B22 -> 4 | F11: ='Model inputs'!B65*'Model inputs'!B22 -> 4 | G11: ='Model inputs'!B65*'Model inputs'!B22 -> 4 | H11: ='Model inputs'!B65*'Model inputs'!B22 -> 4 | I11: ='Model inputs'!B65*'Model inputs'!B22 -> 4 | J11: ='Model inputs'!B65*'Model inputs'!B22 -> 4 | K11: ='Model inputs'!B65*'Model inputs'!B22 -> 4 | L11: ='Model inputs'!B65*'Model inputs'!B22 -> 4 | M11: ='Model inputs'!B65*'Model inputs'!B22 -> 4 | N11: ='Model inputs'!B65*'Model inputs'!B22 -> 4 | O11: ='Model inputs'!B65*'Model inputs'!B22 -> 4 | P11: ='Model inputs'!B65*'Model inputs'!B22 -> 4 | Q11: ='Model inputs'!B65*'Model inputs'!B22 -> 4 | R11: ='Model inputs'!B65*'Model inputs'!B22 -> 4 | S11: ='Model inputs'!B65*'Model inputs'!B22 -> 4
A12: Community | B12: ='Model inputs'!B65*'Model inputs'!B23 -> 0 | C12: ='Model inputs'!B65*'Model inputs'!B23 -> 0 | D12: ='Model inputs'!B65*'Model inputs'!B23 -> 0 | E12: ='Model inputs'!B65*'Model inputs'!B23 -> 0 | F12: ='Model inputs'!B65*'Model inputs'!B23 -> 0 | G12: ='Model inputs'!B65*'Model inputs'!B23 -> 0 | H12: ='Model inputs'!B65*'Model inputs'!B23 -> 0 | I12: ='Model inputs'!B65*'Model inputs'!B23 -> 0 | J12: ='Model inputs'!B65*'Model inputs'!B23 -> 0 | K12: ='Model inputs'!B65*'Model inputs'!B23 -> 0 | L12: ='Model inputs'!B65*'Model inputs'!B23 -> 0 | M12: ='Model inputs'!B65*'Model inputs'!B23 -> 0 | N12: ='Model inputs'!B65*'Model inputs'!B23 -> 0 | O12: ='Model inputs'!B65*'Model inputs'!B23 -> 0 | P12: ='Model inputs'!B65*'Model inputs'!B23 -> 0 | Q12: ='Model inputs'!B65*'Model inputs'!B23 -> 0 | R12: ='Model inputs'!B65*'Model inputs'!B23 -> 0 | S12: ='Model inputs'!B65*'Model inputs'!B23 -> 0
A13: Starter | B13: ='Model inputs'!B65*'Model inputs'!B24 -> 22 | C13: ='Model inputs'!B65*'Model inputs'!B24 -> 22 | D13: ='Model inputs'!B65*'Model inputs'!B24 -> 22 | E13: ='Model inputs'!B65*'Model inputs'!B24 -> 22 | F13: ='Model inputs'!B65*'Model inputs'!B24 -> 22 | G13: ='Model inputs'!B65*'Model inputs'!B24 -> 22 | H13: ='Model inputs'!B65*'Model inputs'!B24 -> 22 | I13: ='Model inputs'!B65*'Model inputs'!B24 -> 22 | J13: ='Model inputs'!B65*'Model inputs'!B24 -> 22 | K13: ='Model inputs'!B65*'Model inputs'!B24 -> 22 | L13: ='Model inputs'!B65*'Model inputs'!B24 -> 22 | M13: ='Model inputs'!B65*'Model inputs'!B24 -> 22 | N13: ='Model inputs'!B65*'Model inputs'!B24 -> 22 | O13: ='Model inputs'!B65*'Model inputs'!B24 -> 22 | P13: ='Model inputs'!B65*'Model inputs'!B24 -> 22 | Q13: ='Model inputs'!B65*'Model inputs'!B24 -> 22 | R13: ='Model inputs'!B65*'Model inputs'!B24 -> 22 | S13: ='Model inputs'!B65*'Model inputs'!B24 -> 22
A14: Team | B14: ='Model inputs'!B65*'Model inputs'!B25 -> 14 | C14: ='Model inputs'!B65*'Model inputs'!B25 -> 14 | D14: ='Model inputs'!B65*'Model inputs'!B25 -> 14 | E14: ='Model inputs'!B65*'Model inputs'!B25 -> 14 | F14: ='Model inputs'!B65*'Model inputs'!B25 -> 14 | G14: ='Model inputs'!B65*'Model inputs'!B25 -> 14 | H14: ='Model inputs'!B65*'Model inputs'!B25 -> 14 | I14: ='Model inputs'!B65*'Model inputs'!B25 -> 14 | J14: ='Model inputs'!B65*'Model inputs'!B25 -> 14 | K14: ='Model inputs'!B65*'Model inputs'!B25 -> 14 | L14: ='Model inputs'!B65*'Model inputs'!B25 -> 14 | M14: ='Model inputs'!B65*'Model inputs'!B25 -> 14 | N14: ='Model inputs'!B65*'Model inputs'!B25 -> 14 | O14: ='Model inputs'!B65*'Model inputs'!B25 -> 14 | P14: ='Model inputs'!B65*'Model inputs'!B25 -> 14 | Q14: ='Model inputs'!B65*'Model inputs'!B25 -> 14 | R14: ='Model inputs'!B65*'Model inputs'!B25 -> 14 | S14: ='Model inputs'!B65*'Model inputs'!B25 -> 14
A15: NW Churned customers | B15: =SUM('Low-price monthly forecast'!B16,'Low-price monthly forecast'!B17,'Low-price monthly forecast'!B18,'Low-price monthly forecast'!B19) -> 0 | C15: =SUM('Low-price monthly forecast'!C16,'Low-price monthly forecast'!C17,'Low-price monthly forecast'!C18,'Low-price monthly forecast'!C19) -> 1.6 | D15: =SUM('Low-price monthly forecast'!D16,'Low-price monthly forecast'!D17,'Low-price monthly forecast'!D18,'Low-price monthly forecast'!D19) -> 3.136 | E15: =SUM('Low-price monthly forecast'!E16,'Low-price monthly forecast'!E17,'Low-price monthly forecast'!E18,'Low-price monthly forecast'!E19) -> 4.61056 | F15: =SUM('Low-price monthly forecast'!F16,'Low-price monthly forecast'!F17,'Low-price monthly forecast'!F18,'Low-price monthly forecast'!F19) -> 6.0261376 | G15: =SUM('Low-price monthly forecast'!G16,'Low-price monthly forecast'!G17,'Low-price monthly forecast'!G18,'Low-price monthly forecast'!G19) -> 7.3850921 | H15: =SUM('Low-price monthly forecast'!H16,'Low-price monthly forecast'!H17,'Low-price monthly forecast'!H18,'Low-price monthly forecast'!H19) -> 8.6896884 | I15: =SUM('Low-price monthly forecast'!I16,'Low-price monthly forecast'!I17,'Low-price monthly forecast'!I18,'Low-price monthly forecast'!I19) -> 9.9421009 | ... S15: =SUM('Low-price monthly forecast'!S16,'Low-price monthly forecast'!S17,'Low-price monthly forecast'!S18,'Low-price monthly forecast'!S19) -> 20.016528
A16: Business | B16: ='Low-price monthly forecast'!B6*'Model inputs'!B59 -> 0 | C16: ='Low-price monthly forecast'!C6*'Model inputs'!B59 -> 0.16 | D16: ='Low-price monthly forecast'!D6*'Model inputs'!B59 -> 0.3136 | E16: ='Low-price monthly forecast'!E6*'Model inputs'!B59 -> 0.461056 | F16: ='Low-price monthly forecast'!F6*'Model inputs'!B59 -> 0.60261376 | G16: ='Low-price monthly forecast'!G6*'Model inputs'!B59 -> 0.73850921 | H16: ='Low-price monthly forecast'!H6*'Model inputs'!B59 -> 0.86896884 | I16: ='Low-price monthly forecast'!I6*'Model inputs'!B59 -> 0.99421009 | J16: ='Low-price monthly forecast'!J6*'Model inputs'!B59 -> 1.1144417 | K16: ='Low-price monthly forecast'!K6*'Model inputs'!B59 -> 1.229864 | L16: ='Low-price monthly forecast'!L6*'Model inputs'!B59 -> 1.3406695 | M16: ='Low-price monthly forecast'!M6*'Model inputs'!B59 -> 1.4470427 | N16: ='Low-price monthly forecast'!N6*'Model inputs'!B59 -> 1.549161 | O16: ='Low-price monthly forecast'!O6*'Model inputs'!B59 -> 1.6471945 | P16: ='Low-price monthly forecast'!P6*'Model inputs'!B59 -> 1.7413068 | Q16: ='Low-price monthly forecast'!Q6*'Model inputs'!B59 -> 1.8316545 | R16: ='Low-price monthly forecast'!R6*'Model inputs'!B59 -> 1.9183883 | S16: ='Low-price monthly forecast'!S6*'Model inputs'!B59 -> 2.0016528
A17: Community | B17: ='Low-price monthly forecast'!B7*'Model inputs'!B59 -> 0 | C17: ='Low-price monthly forecast'!C7*'Model inputs'!B59 -> 0 | D17: ='Low-price monthly forecast'!D7*'Model inputs'!B59 -> 0 | E17: ='Low-price monthly forecast'!E7*'Model inputs'!B59 -> 0 | F17: ='Low-price monthly forecast'!F7*'Model inputs'!B59 -> 0 | G17: ='Low-price monthly forecast'!G7*'Model inputs'!B59 -> 0 | H17: ='Low-price monthly forecast'!H7*'Model inputs'!B59 -> 0 | I17: ='Low-price monthly forecast'!I7*'Model inputs'!B59 -> 0 | J17: ='Low-price monthly forecast'!J7*'Model inputs'!B59 -> 0 | K17: ='Low-price monthly forecast'!K7*'Model inputs'!B59 -> 0 | L17: ='Low-price monthly forecast'!L7*'Model inputs'!B59 -> 0 | M17: ='Low-price monthly forecast'!M7*'Model inputs'!B59 -> 0 | N17: ='Low-price monthly forecast'!N7*'Model inputs'!B59 -> 0 | O17: ='Low-price monthly forecast'!O7*'Model inputs'!B59 -> 0 | P17: ='Low-price monthly forecast'!P7*'Model inputs'!B59 -> 0 | Q17: ='Low-price monthly forecast'!Q7*'Model inputs'!B59 -> 0 | R17: ='Low-price monthly forecast'!R7*'Model inputs'!B59 -> 0 | S17: ='Low-price monthly forecast'!S7*'Model inputs'!B59 -> 0
A18: Starter | B18: ='Low-price monthly forecast'!B8*'Model inputs'!B59 -> 0 | C18: ='Low-price monthly forecast'!C8*'Model inputs'!B59 -> 0.88 | D18: ='Low-price monthly forecast'!D8*'Model inputs'!B59 -> 1.7248 | E18: ='Low-price monthly forecast'!E8*'Model inputs'!B59 -> 2.535808 | F18: ='Low-price monthly forecast'!F8*'Model inputs'!B59 -> 3.3143757 | G18: ='Low-price monthly forecast'!G8*'Model inputs'!B59 -> 4.0618007 | H18: ='Low-price monthly forecast'!H8*'Model inputs'!B59 -> 4.7793286 | I18: ='Low-price monthly forecast'!I8*'Model inputs'!B59 -> 5.4681555 | J18: ='Low-price monthly forecast'!J8*'Model inputs'!B59 -> 6.1294293 | K18: ='Low-price monthly forecast'!K8*'Model inputs'!B59 -> 6.7642521 | L18: ='Low-price monthly forecast'!L8*'Model inputs'!B59 -> 7.373682 | M18: ='Low-price monthly forecast'!M8*'Model inputs'!B59 -> 7.9587347 | N18: ='Low-price monthly forecast'!N8*'Model inputs'!B59 -> 8.5203853 | O18: ='Low-price monthly forecast'!O8*'Model inputs'!B59 -> 9.0595699 | P18: ='Low-price monthly forecast'!P8*'Model inputs'!B59 -> 9.5771871 | Q18: ='Low-price monthly forecast'!Q8*'Model inputs'!B59 -> 10.0741 | R18: ='Low-price monthly forecast'!R8*'Model inputs'!B59 -> 10.551136 | S18: ='Low-price monthly forecast'!S8*'Model inputs'!B59 -> 11.00909
A19: Team | B19: ='Low-price monthly forecast'!B9*'Model inputs'!B59 -> 0 | C19: ='Low-price monthly forecast'!C9*'Model inputs'!B59 -> 0.56 | D19: ='Low-price monthly forecast'!D9*'Model inputs'!B59 -> 1.0976 | E19: ='Low-price monthly forecast'!E9*'Model inputs'!B59 -> 1.613696 | F19: ='Low-price monthly forecast'!F9*'Model inputs'!B59 -> 2.1091482 | G19: ='Low-price monthly forecast'!G9*'Model inputs'!B59 -> 2.5847822 | H19: ='Low-price monthly forecast'!H9*'Model inputs'!B59 -> 3.0413909 | I19: ='Low-price monthly forecast'!I9*'Model inputs'!B59 -> 3.4797353 | J19: ='Low-price monthly forecast'!J9*'Model inputs'!B59 -> 3.9005459 | K19: ='Low-price monthly forecast'!K9*'Model inputs'!B59 -> 4.3045241 | L19: ='Low-price monthly forecast'!L9*'Model inputs'!B59 -> 4.6923431 | M19: ='Low-price monthly forecast'!M9*'Model inputs'!B59 -> 5.0646494 | N19: ='Low-price monthly forecast'!N9*'Model inputs'!B59 -> 5.4220634 | O19: ='Low-price monthly forecast'!O9*'Model inputs'!B59 -> 5.7651809 | P19: ='Low-price monthly forecast'!P9*'Model inputs'!B59 -> 6.0945736 | Q19: ='Low-price monthly forecast'!Q9*'Model inputs'!B59 -> 6.4107907 | R19: ='Low-price monthly forecast'!R9*'Model inputs'!B59 -> 6.7143591 | S19: ='Low-price monthly forecast'!S9*'Model inputs'!B59 -> 7.0057847
A20: NW Paying customers | B20: =SUM('Low-price monthly forecast'!B21,'Low-price monthly forecast'!B22,'Low-price monthly forecast'!B23,'Low-price monthly forecast'!B24) -> 40 | C20: =SUM('Low-price monthly forecast'!C21,'Low-price monthly forecast'!C22,'Low-price monthly forecast'!C23,'Low-price monthly forecast'!C24) -> 78.4 | D20: =SUM('Low-price monthly forecast'!D21,'Low-price monthly forecast'!D22,'Low-price monthly forecast'!D23,'Low-price monthly forecast'!D24) -> 115.264 | E20: =SUM('Low-price monthly forecast'!E21,'Low-price monthly forecast'!E22,'Low-price monthly forecast'!E23,'Low-price monthly forecast'!E24) -> 150.65344 | F20: =SUM('Low-price monthly forecast'!F21,'Low-price monthly forecast'!F22,'Low-price monthly forecast'!F23,'Low-price monthly forecast'!F24) -> 184.6273 | G20: =SUM('Low-price monthly forecast'!G21,'Low-price monthly forecast'!G22,'Low-price monthly forecast'!G23,'Low-price monthly forecast'!G24) -> 217.24221 | H20: =SUM('Low-price monthly forecast'!H21,'Low-price monthly forecast'!H22,'Low-price monthly forecast'!H23,'Low-price monthly forecast'!H24) -> 248.55252 | I20: =SUM('Low-price monthly forecast'!I21,'Low-price monthly forecast'!I22,'Low-price monthly forecast'!I23,'Low-price monthly forecast'!I24) -> 278.61042 | ... S20: =SUM('Low-price monthly forecast'!S21,'Low-price monthly forecast'!S22,'Low-price monthly forecast'!S23,'Low-price monthly forecast'!S24) -> 520.39666
A21: Business | B21: ='Low-price monthly forecast'!B6+'Low-price monthly forecast'!B11-'Low-price monthly forecast'!B16 -> 4 | C21: ='Low-price monthly forecast'!C6+'Low-price monthly forecast'!C11-'Low-price monthly forecast'!C16 -> 7.84 | D21: ='Low-price monthly forecast'!D6+'Low-price monthly forecast'!D11-'Low-price monthly forecast'!D16 -> 11.5264 | E21: ='Low-price monthly forecast'!E6+'Low-price monthly forecast'!E11-'Low-price monthly forecast'!E16 -> 15.065344 | F21: ='Low-price monthly forecast'!F6+'Low-price monthly forecast'!F11-'Low-price monthly forecast'!F16 -> 18.46273 | G21: ='Low-price monthly forecast'!G6+'Low-price monthly forecast'!G11-'Low-price monthly forecast'!G16 -> 21.724221 | H21: ='Low-price monthly forecast'!H6+'Low-price monthly forecast'!H11-'Low-price monthly forecast'!H16 -> 24.855252 | I21: ='Low-price monthly forecast'!I6+'Low-price monthly forecast'!I11-'Low-price monthly forecast'!I16 -> 27.861042 | ... S21: ='Low-price monthly forecast'!S6+'Low-price monthly forecast'!S11-'Low-price monthly forecast'!S16 -> 52.039666
A22: Community | B22: ='Low-price monthly forecast'!B7+'Low-price monthly forecast'!B12-'Low-price monthly forecast'!B17 -> 0 | C22: ='Low-price monthly forecast'!C7+'Low-price monthly forecast'!C12-'Low-price monthly forecast'!C17 -> 0 | D22: ='Low-price monthly forecast'!D7+'Low-price monthly forecast'!D12-'Low-price monthly forecast'!D17 -> 0 | E22: ='Low-price monthly forecast'!E7+'Low-price monthly forecast'!E12-'Low-price monthly forecast'!E17 -> 0 | F22: ='Low-price monthly forecast'!F7+'Low-price monthly forecast'!F12-'Low-price monthly forecast'!F17 -> 0 | G22: ='Low-price monthly forecast'!G7+'Low-price monthly forecast'!G12-'Low-price monthly forecast'!G17 -> 0 | H22: ='Low-price monthly forecast'!H7+'Low-price monthly forecast'!H12-'Low-price monthly forecast'!H17 -> 0 | I22: ='Low-price monthly forecast'!I7+'Low-price monthly forecast'!I12-'Low-price monthly forecast'!I17 -> 0 | ... S22: ='Low-price monthly forecast'!S7+'Low-price monthly forecast'!S12-'Low-price monthly forecast'!S17 -> 0
A23: Starter | B23: ='Low-price monthly forecast'!B8+'Low-price monthly forecast'!B13-'Low-price monthly forecast'!B18 -> 22 | C23: ='Low-price monthly forecast'!C8+'Low-price monthly forecast'!C13-'Low-price monthly forecast'!C18 -> 43.12 | D23: ='Low-price monthly forecast'!D8+'Low-price monthly forecast'!D13-'Low-price monthly forecast'!D18 -> 63.3952 | E23: ='Low-price monthly forecast'!E8+'Low-price monthly forecast'!E13-'Low-price monthly forecast'!E18 -> 82.859392 | F23: ='Low-price monthly forecast'!F8+'Low-price monthly forecast'!F13-'Low-price monthly forecast'!F18 -> 101.54502 | G23: ='Low-price monthly forecast'!G8+'Low-price monthly forecast'!G13-'Low-price monthly forecast'!G18 -> 119.48322 | H23: ='Low-price monthly forecast'!H8+'Low-price monthly forecast'!H13-'Low-price monthly forecast'!H18 -> 136.70389 | I23: ='Low-price monthly forecast'!I8+'Low-price monthly forecast'!I13-'Low-price monthly forecast'!I18 -> 153.23573 | ... S23: ='Low-price monthly forecast'!S8+'Low-price monthly forecast'!S13-'Low-price monthly forecast'!S18 -> 286.21817
A24: Team | B24: ='Low-price monthly forecast'!B9+'Low-price monthly forecast'!B14-'Low-price monthly forecast'!B19 -> 14 | C24: ='Low-price monthly forecast'!C9+'Low-price monthly forecast'!C14-'Low-price monthly forecast'!C19 -> 27.44 | D24: ='Low-price monthly forecast'!D9+'Low-price monthly forecast'!D14-'Low-price monthly forecast'!D19 -> 40.3424 | E24: ='Low-price monthly forecast'!E9+'Low-price monthly forecast'!E14-'Low-price monthly forecast'!E19 -> 52.728704 | F24: ='Low-price monthly forecast'!F9+'Low-price monthly forecast'!F14-'Low-price monthly forecast'!F19 -> 64.619556 | G24: ='Low-price monthly forecast'!G9+'Low-price monthly forecast'!G14-'Low-price monthly forecast'!G19 -> 76.034774 | H24: ='Low-price monthly forecast'!H9+'Low-price monthly forecast'!H14-'Low-price monthly forecast'!H19 -> 86.993383 | I24: ='Low-price monthly forecast'!I9+'Low-price monthly forecast'!I14-'Low-price monthly forecast'!I19 -> 97.513647 | ... S24: ='Low-price monthly forecast'!S9+'Low-price monthly forecast'!S14-'Low-price monthly forecast'!S19 -> 182.13883
A25: NW Subscription revenue | B25: =SUM('Low-price monthly forecast'!B26,'Low-price monthly forecast'!B27,'Low-price monthly forecast'!B28,'Low-price monthly forecast'!B29) -> 1154 | C25: =SUM('Low-price monthly forecast'!C26,'Low-price monthly forecast'!C27,'Low-price monthly forecast'!C28,'Low-price monthly forecast'!C29) -> 2261.84 | D25: =SUM('Low-price monthly forecast'!D26,'Low-price monthly forecast'!D27,'Low-price monthly forecast'!D28,'Low-price monthly forecast'!D29) -> 3325.3664 | E25: =SUM('Low-price monthly forecast'!E26,'Low-price monthly forecast'!E27,'Low-price monthly forecast'!E28,'Low-price monthly forecast'!E29) -> 4346.3517 | F25: =SUM('Low-price monthly forecast'!F26,'Low-price monthly forecast'!F27,'Low-price monthly forecast'!F28,'Low-price monthly forecast'!F29) -> 5326.4977 | G25: =SUM('Low-price monthly forecast'!G26,'Low-price monthly forecast'!G27,'Low-price monthly forecast'!G28,'Low-price monthly forecast'!G29) -> 6267.4378 | H25: =SUM('Low-price monthly forecast'!H26,'Low-price monthly forecast'!H27,'Low-price monthly forecast'!H28,'Low-price monthly forecast'!H29) -> 7170.7403 | I25: =SUM('Low-price monthly forecast'!I26,'Low-price monthly forecast'!I27,'Low-price monthly forecast'!I28,'Low-price monthly forecast'!I29) -> 8037.9106 | ... S25: =SUM('Low-price monthly forecast'!S26,'Low-price monthly forecast'!S27,'Low-price monthly forecast'!S28,'Low-price monthly forecast'!S29) -> 15013.444
A26: Business | B26: ='Low-price monthly forecast'!B21*'Model inputs'!B94 -> 624 | C26: ='Low-price monthly forecast'!C21*'Model inputs'!B94 -> 1223.04 | D26: ='Low-price monthly forecast'!D21*'Model inputs'!B94 -> 1798.1184 | E26: ='Low-price monthly forecast'!E21*'Model inputs'!B94 -> 2350.1937 | F26: ='Low-price monthly forecast'!F21*'Model inputs'!B94 -> 2880.1859 | G26: ='Low-price monthly forecast'!G21*'Model inputs'!B94 -> 3388.9785 | H26: ='Low-price monthly forecast'!H21*'Model inputs'!B94 -> 3877.4193 | I26: ='Low-price monthly forecast'!I21*'Model inputs'!B94 -> 4346.3226 | J26: ='Low-price monthly forecast'!J21*'Model inputs'!B94 -> 4796.4697 | K26: ='Low-price monthly forecast'!K21*'Model inputs'!B94 -> 5228.6109 | L26: ='Low-price monthly forecast'!L21*'Model inputs'!B94 -> 5643.4664 | M26: ='Low-price monthly forecast'!M21*'Model inputs'!B94 -> 6041.7278 | N26: ='Low-price monthly forecast'!N21*'Model inputs'!B94 -> 6424.0587 | O26: ='Low-price monthly forecast'!O21*'Model inputs'!B94 -> 6791.0963 | P26: ='Low-price monthly forecast'!P21*'Model inputs'!B94 -> 7143.4525 | Q26: ='Low-price monthly forecast'!Q21*'Model inputs'!B94 -> 7481.7144 | R26: ='Low-price monthly forecast'!R21*'Model inputs'!B94 -> 7806.4458 | S26: ='Low-price monthly forecast'!S21*'Model inputs'!B94 -> 8118.188
A27: Community | B27: ='Low-price monthly forecast'!B22*'Model inputs'!B95 -> 0 | C27: ='Low-price monthly forecast'!C22*'Model inputs'!B95 -> 0 | D27: ='Low-price monthly forecast'!D22*'Model inputs'!B95 -> 0 | E27: ='Low-price monthly forecast'!E22*'Model inputs'!B95 -> 0 | F27: ='Low-price monthly forecast'!F22*'Model inputs'!B95 -> 0 | G27: ='Low-price monthly forecast'!G22*'Model inputs'!B95 -> 0 | H27: ='Low-price monthly forecast'!H22*'Model inputs'!B95 -> 0 | I27: ='Low-price monthly forecast'!I22*'Model inputs'!B95 -> 0 | J27: ='Low-price monthly forecast'!J22*'Model inputs'!B95 -> 0 | K27: ='Low-price monthly forecast'!K22*'Model inputs'!B95 -> 0 | L27: ='Low-price monthly forecast'!L22*'Model inputs'!B95 -> 0 | M27: ='Low-price monthly forecast'!M22*'Model inputs'!B95 -> 0 | N27: ='Low-price monthly forecast'!N22*'Model inputs'!B95 -> 0 | O27: ='Low-price monthly forecast'!O22*'Model inputs'!B95 -> 0 | P27: ='Low-price monthly forecast'!P22*'Model inputs'!B95 -> 0 | Q27: ='Low-price monthly forecast'!Q22*'Model inputs'!B95 -> 0 | R27: ='Low-price monthly forecast'!R22*'Model inputs'!B95 -> 0 | S27: ='Low-price monthly forecast'!S22*'Model inputs'!B95 -> 0
A28: Starter | B28: ='Low-price monthly forecast'!B23*'Model inputs'!B96 -> 110 | C28: ='Low-price monthly forecast'!C23*'Model inputs'!B96 -> 215.6 | D28: ='Low-price monthly forecast'!D23*'Model inputs'!B96 -> 316.976 | E28: ='Low-price monthly forecast'!E23*'Model inputs'!B96 -> 414.29696 | F28: ='Low-price monthly forecast'!F23*'Model inputs'!B96 -> 507.72508 | G28: ='Low-price monthly forecast'!G23*'Model inputs'!B96 -> 597.41608 | H28: ='Low-price monthly forecast'!H23*'Model inputs'!B96 -> 683.51944 | I28: ='Low-price monthly forecast'!I23*'Model inputs'!B96 -> 766.17866 | J28: ='Low-price monthly forecast'!J23*'Model inputs'!B96 -> 845.53151 | K28: ='Low-price monthly forecast'!K23*'Model inputs'!B96 -> 921.71025 | L28: ='Low-price monthly forecast'!L23*'Model inputs'!B96 -> 994.84184 | M28: ='Low-price monthly forecast'!M23*'Model inputs'!B96 -> 1065.0482 | N28: ='Low-price monthly forecast'!N23*'Model inputs'!B96 -> 1132.4462 | O28: ='Low-price monthly forecast'!O23*'Model inputs'!B96 -> 1197.1484 | P28: ='Low-price monthly forecast'!P23*'Model inputs'!B96 -> 1259.2625 | Q28: ='Low-price monthly forecast'!Q23*'Model inputs'!B96 -> 1318.892 | R28: ='Low-price monthly forecast'!R23*'Model inputs'!B96 -> 1376.1363 | S28: ='Low-price monthly forecast'!S23*'Model inputs'!B96 -> 1431.0908
A29: Team | B29: ='Low-price monthly forecast'!B24*'Model inputs'!B97 -> 420 | C29: ='Low-price monthly forecast'!C24*'Model inputs'!B97 -> 823.2 | D29: ='Low-price monthly forecast'!D24*'Model inputs'!B97 -> 1210.272 | E29: ='Low-price monthly forecast'!E24*'Model inputs'!B97 -> 1581.8611 | F29: ='Low-price monthly forecast'!F24*'Model inputs'!B97 -> 1938.5867 | G29: ='Low-price monthly forecast'!G24*'Model inputs'!B97 -> 2281.0432 | H29: ='Low-price monthly forecast'!H24*'Model inputs'!B97 -> 2609.8015 | I29: ='Low-price monthly forecast'!I24*'Model inputs'!B97 -> 2925.4094 | J29: ='Low-price monthly forecast'!J24*'Model inputs'!B97 -> 3228.393 | K29: ='Low-price monthly forecast'!K24*'Model inputs'!B97 -> 3519.2573 | L29: ='Low-price monthly forecast'!L24*'Model inputs'!B97 -> 3798.487 | M29: ='Low-price monthly forecast'!M24*'Model inputs'!B97 -> 4066.5475 | N29: ='Low-price monthly forecast'!N24*'Model inputs'!B97 -> 4323.8856 | O29: ='Low-price monthly forecast'!O24*'Model inputs'!B97 -> 4570.9302 | P29: ='Low-price monthly forecast'!P24*'Model inputs'!B97 -> 4808.093 | Q29: ='Low-price monthly forecast'!Q24*'Model inputs'!B97 -> 5035.7693 | R29: ='Low-price monthly forecast'!R24*'Model inputs'!B97 -> 5254.3385 | S29: ='Low-price monthly forecast'!S24*'Model inputs'!B97 -> 5464.165
A30: NW Overage revenue | B30: =SUM('Low-price monthly forecast'!B31,'Low-price monthly forecast'!B32,'Low-price monthly forecast'!B33,'Low-price monthly forecast'!B34) -> 0 | C30: =SUM('Low-price monthly forecast'!C31,'Low-price monthly forecast'!C32,'Low-price monthly forecast'!C33,'Low-price monthly forecast'!C34) -> 0 | D30: =SUM('Low-price monthly forecast'!D31,'Low-price monthly forecast'!D32,'Low-price monthly forecast'!D33,'Low-price monthly forecast'!D34) -> 0 | E30: =SUM('Low-price monthly forecast'!E31,'Low-price monthly forecast'!E32,'Low-price monthly forecast'!E33,'Low-price monthly forecast'!E34) -> 0 | F30: =SUM('Low-price monthly forecast'!F31,'Low-price monthly forecast'!F32,'Low-price monthly forecast'!F33,'Low-price monthly forecast'!F34) -> 0 | G30: =SUM('Low-price monthly forecast'!G31,'Low-price monthly forecast'!G32,'Low-price monthly forecast'!G33,'Low-price monthly forecast'!G34) -> 0 | H30: =SUM('Low-price monthly forecast'!H31,'Low-price monthly forecast'!H32,'Low-price monthly forecast'!H33,'Low-price monthly forecast'!H34) -> 0 | I30: =SUM('Low-price monthly forecast'!I31,'Low-price monthly forecast'!I32,'Low-price monthly forecast'!I33,'Low-price monthly forecast'!I34) -> 0 | ... S30: =SUM('Low-price monthly forecast'!S31,'Low-price monthly forecast'!S32,'Low-price monthly forecast'!S33,'Low-price monthly forecast'!S34) -> 0
A31: Business | B31: ='Low-price monthly forecast'!B21*'Model inputs'!B73 -> 0 | C31: ='Low-price monthly forecast'!C21*'Model inputs'!B73 -> 0 | D31: ='Low-price monthly forecast'!D21*'Model inputs'!B73 -> 0 | E31: ='Low-price monthly forecast'!E21*'Model inputs'!B73 -> 0 | F31: ='Low-price monthly forecast'!F21*'Model inputs'!B73 -> 0 | G31: ='Low-price monthly forecast'!G21*'Model inputs'!B73 -> 0 | H31: ='Low-price monthly forecast'!H21*'Model inputs'!B73 -> 0 | I31: ='Low-price monthly forecast'!I21*'Model inputs'!B73 -> 0 | J31: ='Low-price monthly forecast'!J21*'Model inputs'!B73 -> 0 | K31: ='Low-price monthly forecast'!K21*'Model inputs'!B73 -> 0 | L31: ='Low-price monthly forecast'!L21*'Model inputs'!B73 -> 0 | M31: ='Low-price monthly forecast'!M21*'Model inputs'!B73 -> 0 | N31: ='Low-price monthly forecast'!N21*'Model inputs'!B73 -> 0 | O31: ='Low-price monthly forecast'!O21*'Model inputs'!B73 -> 0 | P31: ='Low-price monthly forecast'!P21*'Model inputs'!B73 -> 0 | Q31: ='Low-price monthly forecast'!Q21*'Model inputs'!B73 -> 0 | R31: ='Low-price monthly forecast'!R21*'Model inputs'!B73 -> 0 | S31: ='Low-price monthly forecast'!S21*'Model inputs'!B73 -> 0
